Workbook

Sheet 표지·요약
B2: [지역명] 팝업·공실 매칭 IT 플랫폼 구축 사업
B3: 예 산 안 (Draft) — IT 영역
B4: 당신의 아이디어가 머물 자리. · Empty rooms, full of possibilities.
B6: 단위: 원 (₩) · 부가세 별도 · 사업 기간 2026. 6. ~ 2027. 12. · 본 예산 범위: 구축기 (2026. 6. ~ 2026. 12., 6개월)
B7: 작성: [운영기관] / 2026. 5.
B9: ■ 시나리오별 예산 규모
B10: 기준안 | C10: 300000000
B11: 확장안 | C11: 500000000
B14: 대분류 | C14: 기준안 (3억) | D14: 확장안 (5억) | E14: 비중 (기준안) | F14: 비고
B15: 1. 인프라·클라우드 | C15: =상세!H12 -> 19100000 | D15: =상세!L12 -> 33500000 | E15: =C15/C$25 -> 0.063666667 | F15: 서버·DB·CDN·모니터링 등 클라우드 운영 인프라
B16: 2. AI·외부 API | C16: =상세!H24 -> 17700000 | D16: =상세!L24 -> 30300000 | E16: =C16/C$25 -> 0.059 | F16: LLM·지도·결제·알림톡 등 외부 API 사용량 기반
B17: 3. SW 라이센스·툴 | C17: =상세!H34 -> 7900000 | D17: =상세!L34 -> 14000000 | E17: =C17/C$25 -> 0.026333333 | F17: 개발·디자인·분석 협업 도구
B18: 4. 개발 인건비 (외주·계약) | C18: =상세!H43 -> 135300000 | D18: =상세!L43 -> 225900000 | E18: =C18/C$25 -> 0.451 | F18: 프론트·백엔드·AI/ML·디자인 외주 인건비
B19: 5. 디자인·콘텐츠 | C19: =상세!H53 -> 29000000 | D19: =상세!L53 -> 46700000 | E19: =C19/C$25 -> 0.096666667 | F19: BI·디자인 시스템·사진·매거진 콘텐츠 제작
B20: 6. 데이터 구축 | C20: =상세!H62 -> 16150000 | D20: =상세!L62 -> 28800000 | E20: =C20/C$25 -> 0.053833333 | F20: 공실·상권·행정 데이터 수집·정제·DB 구축
B21: 7. 보안·법무·인증 | C21: =상세!H71 -> 12000000 | D21: =상세!L71 -> 20000000 | E21: =C21/C$25 -> 0.04 | F21: 보안 진단·개인정보·법무 자문·보험
B22: 8. 운영·고객지원 | C22: =상세!H79 -> 18150000 | D22: =상세!L79 -> 28600000 | E22: =C22/C$25 -> 0.0605 | F22: CS·운영 매니저·매뉴얼·정기 점검
B23: 9. 마케팅 (IT 영역) | C23: =상세!H88 -> 21200000 | D23: =상세!L88 -> 31700000 | E23: =C23/C$25 -> 0.070666667 | F23: SEO·디지털 광고·랜딩 페이지·PR
B24: 10. 사업관리·예비비 | C24: =상세!H95 -> 23500000 | D24: =상세!L95 -> 40500000 | E24: =C24/C$25 -> 0.078333333 | F24: 총괄 PM·회계·일반관리비·예비비
B25: 합 계 | C25: =SUM(C15:C24) -> 300000000 | D25: =SUM(D15:D24) -> 500000000 | E25: =SUM(E15:E24) -> 1
B27: ※ 부가세는 항목별 별도 산정. 본 예산은 IT 영역에 한함.
B28: ※ 본 예산은 구축기(2026. 6. ~ 2026. 12.) 기준이며, 운영기 이후의 운영비는 사업 진행 결과에 따라 별도 산정함.
B29: ※ 단가는 시장 일반 단가를 기준으로 산정하였으며, 사업 확정 단계에서 견적·계약 시 재산정한다.

Sheet 상세
A1: 번호 | B1: 대분류 | C1: 세부 항목 | D1: 단위 | E1: 수량 | F1: 단가 | G1: 기간 | H1: 기준안 소계 (원) | I1: 수량 | J1: 단가 | K1: 기간 | L1: 확장안 소계 (원) | M1: 비고
E2: ── 기준안 (3억) ── | I2: ── 확장안 (5억) ──
B3: 1. 인프라·클라우드
A4: 1 | C4: 클라우드 컴퓨팅 (Compute, Auto-scaling) | D4: 월 | E4: 1 | F4: 1200000 | G4: 6 | H4: =E4*F4*G4 -> 7200000 | I4: 1 | J4: 2000000 | K4: 6 | L4: =I4*J4*K4 -> 12000000 | M4: AWS/GCP. 트래픽 증가 시 비례 확대
A5: 2 | C5: 매니지드 DB (PostgreSQL, Multi-AZ) | D5: 월 | E5: 1 | F5: 500000 | G5: 6 | H5: =E5*F5*G5 -> 3000000 | I5: 1 | J5: 900000 | K5: 6 | L5: =I5*J5*K5 -> 5400000 | M5: RDS 등. HA 구성
A6: 3 | C6: 캐시·세션 (Redis) | D6: 월 | E6: 1 | F6: 200000 | G6: 6 | H6: =E6*F6*G6 -> 1200000 | I6: 1 | J6: 350000 | K6: 6 | L6: =I6*J6*K6 -> 2100000 | M6: ElastiCache 등
A7: 4 | C7: 오브젝트 스토리지·CDN (이미지·콘텐츠) | D7: 월 | E7: 1 | F7: 300000 | G7: 6 | H7: =E7*F7*G7 -> 1800000 | I7: 1 | J7: 550000 | K7: 6 | L7: =I7*J7*K7 -> 3300000 | M7: S3 + CloudFront
A8: 5 | C8: 도메인·SSL·DNS | D8: 식 | E8: 1 | F8: 500000 | G8: 1 | H8: =E8*F8*G8 -> 500000 | I8: 1 | J8: 800000 | K8: 1 | L8: =I8*J8*K8 -> 800000 | M8: 다년도 갱신 포함
A9: 6 | C9: APM·에러·로그 모니터링 | D9: 월 | E9: 1 | F9: 400000 | G9: 6 | H9: =E9*F9*G9 -> 2400000 | I9: 1 | J9: 800000 | K9: 6 | L9: =I9*J9*K9 -> 4800000 | M9: Sentry/DataDog
A10: 7 | C10: 로그 수집·관측 (Log Analytics) | D10: 월 | E10: 1 | F10: 300000 | G10: 6 | H10: =E10*F10*G10 -> 1800000 | I10: 1 | J10: 600000 | K10: 6 | L10: =I10*J10*K10 -> 3600000 | M10: 이벤트 분석 기반
A11: 8 | C11: 백업·재해복구 | D11: 월 | E11: 1 | F11: 200000 | G11: 6 | H11: =E11*F11*G11 -> 1200000 | I11: 1 | J11: 250000 | K11: 6 | L11: =I11*J11*K11 -> 1500000 | M11: RPO 24h 기준
B12: 1. 인프라·클라우드 소계 | H12: =SUM(H4:H11) -> 19100000 | L12: =SUM(L4:L11) -> 33500000
B13: 2. AI·외부 API
A14: 9 | C14: LLM 토큰 — 콘텐츠·카피 생성 | D14: 월 | E14: 1 | F14: 600000 | G14: 6 | H14: =E14*F14*G14 -> 3600000 | I14: 1 | J14: 1000000 | K14: 6 | L14: =I14*J14*K14 -> 6000000 | M14: OpenAI/Anthropic 사용량 기반
A15: 10 | C15: LLM 토큰 — 매칭 추천·자연어 질의 | D15: 월 | E15: 1 | F15: 400000 | G15: 6 | H15: =E15*F15*G15 -> 2400000 | I15: 1 | J15: 700000 | K15: 6 | L15: =I15*J15*K15 -> 4200000 | M15: 동네·브랜드 적합도 추천
A16: 11 | C16: 임베딩·벡터 DB | D16: 월 | E16: 1 | F16: 200000 | G16: 6 | H16: =E16*F16*G16 -> 1200000 | I16: 1 | J16: 400000 | K16: 6 | L16: =I16*J16*K16 -> 2400000 | M16: Pinecone/PGVector
A17: 12 | C17: 이미지 생성 API (OG·SNS 소재) | D17: 월 | E17: 1 | F17: 200000 | G17: 6 | H17: =E17*F17*G17 -> 1200000 | I17: 1 | J17: 400000 | K17: 6 | L17: =I17*J17*K17 -> 2400000 | M17: 광고 소재 자동화
A18: 13 | C18: 지도 API (지오코딩·POI·라우팅) | D18: 월 | E18: 1 | F18: 350000 | G18: 6 | H18: =E18*F18*G18 -> 2100000 | I18: 1 | J18: 500000 | K18: 6 | L18: =I18*J18*K18 -> 3000000 | M18: 네이버/카카오 지도
A19: 14 | C19: 결제 PG 연동 (고정비) | D19: 월 | E19: 1 | F19: 200000 | G19: 6 | H19: =E19*F19*G19 -> 1200000 | I19: 1 | J19: 300000 | K19: 6 | L19: =I19*J19*K19 -> 1800000 | M19: 거래액 % 수수료는 별도
A20: 15 | C20: SMS·카카오 알림톡 | D20: 월 | E20: 1 | F20: 550000 | G20: 6 | H20: =E20*F20*G20 -> 3300000 | I20: 1 | J20: 1000000 | K20: 6 | L20: =I20*J20*K20 -> 6000000 | M20: 팝업 운영 알림 발송
A21: 16 | C21: 본인인증·CI/DI | D21: 월 | E21: 1 | F21: 150000 | G21: 6 | H21: =E21*F21*G21 -> 900000 | I21: 1 | J21: 250000 | K21: 6 | L21: =I21*J21*K21 -> 1500000 | M21: 임대인·브랜드 인증
A22: 17 | C22: OCR·이미지 분석 | D22: 월 | E22: 1 | F22: 150000 | G22: 6 | H22: =E22*F22*G22 -> 900000 | I22: 1 | J22: 250000 | K22: 6 | L22: =I22*J22*K22 -> 1500000 | M22: 매물 사진 자동 태깅
A23: 18 | C23: 전자계약 API | D23: 월 | E23: 1 | F23: 150000 | G23: 6 | H23: =E23*F23*G23 -> 900000 | I23: 1 | J23: 250000 | K23: 6 | L23: =I23*J23*K23 -> 1500000 | M23: 단기 임대 계약
B24: 2. AI·외부 API 소계 | H24: =SUM(H14:H23) -> 17700000 | L24: =SUM(L14:L23) -> 30300000
B25: 3. SW 라이센스·툴
A26: 19 | C26: 협업툴 (Notion·Slack) 팀 라이센스 | D26: 월 | E26: 8 | F26: 25000 | G26: 6 | H26: =E26*F26*G26 -> 1200000 | I26: 10 | J26: 30000 | K26: 6 | L26: =I26*J26*K26 -> 1800000 | M26: 팀 인원 × 단가
A27: 20 | C27: 디자인툴 (Figma) | D27: 월 | E27: 4 | F27: 25000 | G27: 6 | H27: =E27*F27*G27 -> 600000 | I27: 6 | J27: 30000 | K27: 6 | L27: =I27*J27*K27 -> 1080000 | M27: 디자인·기획 인원
A28: 21 | C28: 코드 저장소·CI/CD (GitHub) | D28: 월 | E28: 8 | F28: 10000 | G28: 6 | H28: =E28*F28*G28 -> 480000 | I28: 10 | J28: 12000 | K28: 6 | L28: =I28*J28*K28 -> 720000 | M28: 개발 인원
A29: 22 | C29: 프로젝트 관리 (Linear/Jira) | D29: 월 | E29: 8 | F29: 15000 | G29: 6 | H29: =E29*F29*G29 -> 720000 | I29: 10 | J29: 20000 | K29: 6 | L29: =I29*J29*K29 -> 1200000 | M29: 팀 라이센스
A30: 23 | C30: 프로덕트 분석 SaaS (Mixpanel/Amplitude) | D30: 월 | E30: 1 | F30: 400000 | G30: 6 | H30: =E30*F30*G30 -> 2400000 | I30: 1 | J30: 700000 | K30: 6 | L30: =I30*J30*K30 -> 4200000 | M30: 행동 분석
A31: 24 | C31: E2E 테스트·QA 자동화 | D31: 월 | E31: 1 | F31: 200000 | G31: 6 | H31: =E31*F31*G31 -> 1200000 | I31: 1 | J31: 400000 | K31: 6 | L31: =I31*J31*K31 -> 2400000 | M31: Playwright Cloud 등
A32: 25 | C32: 폰트·디자인 에셋 라이브러리 | D32: 식 | E32: 1 | F32: 400000 | G32: 1 | H32: =E32*F32*G32 -> 400000 | I32: 1 | J32: 800000 | K32: 1 | L32: =I32*J32*K32 -> 800000 | M32: 상업 라이센스
A33: 26 | C33: 보안 스캔·취약점 진단 도구 | D33: 월 | E33: 1 | F33: 150000 | G33: 6 | H33: =E33*F33*G33 -> 900000 | I33: 1 | J33: 300000 | K33: 6 | L33: =I33*J33*K33 -> 1800000 | M33: SAST/DAST
B34: 3. SW 라이센스·툴 소계 | H34: =SUM(H26:H33) -> 7900000 | L34: =SUM(L26:L33) -> 14000000
B35: 4. 개발 인건비 (외주·계약)
A36: 27 | C36: 프론트엔드 개발 — 시니어 | D36: M/M | E36: 0.8 | F36: 6500000 | G36: 6 | H36: =E36*F36*G36 -> 31200000 | I36: 1 | J36: 9000000 | K36: 6 | L36: =I36*J36*K36 -> 54000000 | M36: 주요 UI·반응형
A37: 28 | C37: 백엔드 개발 — 시니어 | D37: M/M | E37: 0.8 | F37: 7000000 | G37: 6 | H37: =E37*F37*G37 -> 33600000 | I37: 1 | J37: 9500000 | K37: 6 | L37: =I37*J37*K37 -> 57000000 | M37: API·데이터 모델
A38: 29 | C38: 백엔드 개발 — 미들 (도메인) | D38: M/M | E38: 0.5 | F38: 5500000 | G38: 6 | H38: =E38*F38*G38 -> 16500000 | I38: 1 | J38: 6500000 | K38: 6 | L38: =I38*J38*K38 -> 39000000 | M38: 결제·매칭 도메인
A39: 30 | C39: AI/ML 엔지니어 (파트타임) | D39: M/M | E39: 0.3 | F39: 10000000 | G39: 6 | H39: =E39*F39*G39 -> 18000000 | I39: 0.5 | J39: 10000000 | K39: 6 | L39: =I39*J39*K39 -> 30000000 | M39: 추천·자연어 모델
A40: 31 | C40: DevOps·SRE (파트타임) | D40: M/M | E40: 0.2 | F40: 8000000 | G40: 6 | H40: =E40*F40*G40 -> 9600000 | I40: 0.2 | J40: 9000000 | K40: 6 | L40: =I40*J40*K40 -> 10800000 | M40: CI/CD·관측
...

Sheet 작성팀 가이드
B2: 작성팀 가이드 (내부 참고용)
B3: 본 시트는 작성팀 내부 참고용입니다. 외부 제출 시 본 시트는 삭제하시기 바랍니다.
B6: ■ 시트 구성
B7: · 표지·요약 — 시나리오별 예산 규모, 카테고리별 비교
B8: · 상세 — 항목별 단가·수량·기간 모델 (편집은 이 시트에서)
B9: · 작성팀 가이드 — 본 시트 (외부 제출 시 삭제)
B11: ■ 색상 규약
B12: · 노란 배경 + 파란 글씨 — 입력값 (단가·수량·기간). 시나리오 조정 시 여기만 수정
B13: · 크림 배경 — 시나리오 예산 규모 (표지 C10·C11)
B14: · 베이지 배경 — 예비비 단가 (자동 잔액 보정 수식). 직접 편집 금지
B15: · 검은 글씨 — 일반 수식 (소계·합계)
B16: · 초록 글씨 — 다른 시트 참조
... B38: · v1.0 — 전략 회의 결과·단가 출처 확정 반영
