Workbook

Sheet 개요
B4: [지역명] 팝업 타운 조성을 통한 상권 활성화 디지털 플랫폼 구축 사업
B5: 통합 견적서 v1.2 (Draft)
B6: 단위: 원 (₩) · 부가세 별도 · IT 영역
B10: 01 사업 개요
B11: 지역 골목 공실은 단순히 한 점포의 문제가 아니다. 한국부동산원에 따르면 2025년 3분기 전국 중대형 상가 공실률은 13.6%, 비수도권 1층 상가 공실률은 전국 평균을 크게 웃돈다. 그동안의 다양한 활성화 시도들이 단기 효과에 그쳤던 이유는 사람들이 다시 찾아오는 지속가능한 운영 구조를 만들지 못했기 때문이고, 그 본질은 공간마다 그 동네만의 고유성과 이야기가 충분히 담기지 않았기 때문이다.
B15: 본 사업은 각 동네의 이야기를 콘텐츠로 담아 사람들이 일부러 찾아오고 싶은 공간을 조성하고, 이를 진입 장벽이 낮은 단기 팝업 형태로 풀어내 임대인·청년 창작자·시민이 모두 부담 없이 참여할 수 있게 한다. 본 견적서는 11개 솔루션 카테고리로 구성되며, 각 솔루션은 독립적으로 도입·계약 가능하다. 단계별 시트(거리 / 권역 / 광역)에서 단계별 단가가 확장되며, 각 카테고리 헤더 행에 카테고리 합계가, 시트 하단에 총합계가 자동 산정된다.
B19: 02 사용 방법
B20: 1 | C20: 단계별 시트(Street / Town / City)를 펼친다. 각 단계마다 단가 배수가 다르다 (×1.0 / ×1.7 / ×3.0).
B21: 2 | C21: 각 카테고리 헤더 행에 카테고리 합계가 자동 표시되며, 시트 하단에 단계별 총합계가 산정된다.
B22: 3 | C22: [요약] 시트에서 단계별·카테고리별 견적을 한눈에 비교할 수 있다.
B23: 4 | C23: 솔루션 단가는 각 단계 시트에서 자유롭게 수정 가능하며, 카테고리 합계와 총합계가 자동 갱신된다.
B24: 5 | C24: 다른 도시에 적용할 때는 본 파일을 복사한 후 단가만 조정하면 그대로 템플릿 재활용 가능하다.
B27: 03 솔루션 카테고리 (10개)
B28: # | C28: 카테고리 | D28: 테마 | E28: 한 줄 소개
B29: 1 | C29: 공간 | D29: 공실의 단기임대 활성화 / 청년의 무대, 지속가능한 팝업타운 | E29: 지역 공실을 청년·창작자의 단기 팝업 무대로 전환하고, 동네 이야기와 결합해 지속가능한 팝업타운을 조성하는 핵심 인프라.
B30: 2 | C30: 아이템 | D30: 청년 아이템·특산물의 시장 검증 | E30: 청년 크리에이터·특산물 생산자가 좋은 상품을 도시 소비자에게 부담 없이 검증할 수 있는 IT 자산. AI 매장 운영 도구로 작은 브랜드도 전문가급 매장 운영.
B31: 3 | C31: 이벤트 | D31: 페스티벌·야시장·영화제의 디지털 운영 | E31: 야시장·페스티벌·영화제 등 지역 행사를 거리 단위 작은 행사부터 광역 단위 대형 행사까지 동일 인프라로 운영. 운영 효율과 데이터 자산 동시 확보.
B32: 4 | C32: 네트워크·시너지 | D32: 거리 → 권역 → 광역 활성화 | E32: 거리 하나의 성공이 옆 거리, 권역, 광역 전체의 활력으로 누적·확산되는 단계적 모델을 시각화·자동화. 사업이 끝난 뒤에도 디지털 자산이 누적되어 다음 거리·다음 권역의 출발점이 된다.
B33: 5 | C33: 멤버십·지역화폐 | D33: 1회 방문자를 도시의 팬으로 | E33: 1회 방문을 지속 재방문·재구매로 전환하는 인센티브 구조. 기존 지자체 지역화폐와 연동해 본 사업의 모든 활동이 지자체 정책 효과 확장으로 이어진다.
B34: 6 | C34: 성과 시각화·리포트 | D34: 지자체 정책의 영구적 근거 자산 | E34: 운영 결과 데이터를 표준화된 형태로 시각화·리포트화. 지자체가 정책 효과를 즉시 보고, 향후 정책 결정·학술 연구·민간 협력에 활용.
B35: 7 | C35: 미션 베이스 인재 매칭 | D35: 지역 청년 유출·소도시 인구 감소 대응 | E35: 일반 시간·임금 위주 구인구직과 달리 비전·미션 기반. 청년이 자기 결을 살려 지역에서 활동할 수 있는 환경을 만들어, 청년 유출과 소도시 인구 감소에 직접 대응.
B36: 8 | C36: 포용성·도시 가족 | D36: 고령화·출산·다문화 등 정주 환경 대응 (안내 IT 중심) | E36: 물리적 시설 신축이 아닌, 기존 시설의 등록·안내·매칭 IT 서비스. 고령화·출산·다문화 등 소도시 정주 환경 정책에 시민 만족도 차원에서 직접 영향.
B37: 9 | C37: 기업 유치·투자 | D37: 지자체 인구·세수·일자리 목표 직결 | E37: 지역 활성화 데이터를 근거로 빅브랜드·자본·창업가·기업을 지역과 연결. 지자체의 본질적 인구·세수·일자리 목표에 직결.
B38: 10 | C38: ESG | D38: 지자체 ESG 평가·정책 대응 | E38: 지자체가 정책·평가·보고에서 직접 필요로 하는 ESG 영역에 IT로 대응. Environment(친환경 운영), Social(시민·소상공인 사회 임팩트), Governance(지자체-운영팀-시민 협력 거버넌스).
B39: 11 | C39: 기타 | D39: 시장 검증된 큰 운영 기능 | E39: 이미 시장에서 검증된 큰 운영 기능들. 단독으로도 임팩트가 큰 솔루션 모음.
B42: 04 색상 규약
C43: 검은 배경 + 흰 글씨 | D43: 헤더 및 총합계 행
C44: 베이지 배경 | D44: 카테고리 헤더 (카테고리 합계 포함)
C45: 연한 베이지 | D45: 솔루션 행 줄무늬
C46: 오렌지 | D46: 카테고리 번호 배지·액센트
B49: 단가는 시장 일반 기준 산정이며, 사업 확정 단계에서 견적·계약 시 재산정한다.

Sheet 거리
B4: 거리 단계 — 단일 거리 활성화
B5: 단가 배수: ×1.0 (거리 기준) · 단위: 원 (₩) · 부가세 별도
B7: 코드 | C7: 솔루션명 | D7: 한 줄 설명 | E7: 단가 (원)
B8: 1 | C8: 공간 · 공실의 단기임대 활성화 / 청년의 무대, 지속가능한 팝업타운 | E8: =SUM(E9:E16) -> 135000000
B9: 1-1 | C9: 로컬 스토리 아카이브·콘텐츠 자산화 플랫폼 | D9: 동네 인물·노포·골목 서사를 위치·테마로 구조화 등록, QR 스토리·전시·오디오 가이드로 재가공. 사업 종료 후에도 남는 영구 콘텐츠 자산 | E9: 25000000
B10: 1-2 | C10: 임대 매물 등록·관리 시스템 | D10: 수요자·공급자 양방향 등록, 매물 정보·일정·상태 관리 | E10: 15000000
B11: 1-3 | C11: 공실 현황 GIS 지도 시스템 | D11: 지역 공실·매물을 지도에 실시간 표시, 권역·시기별 공실률·전환율 시각화. 지자체가 공실 분포를 한눈에 파악 | E11: 15000000
B12: 1-4 | C12: AI 매물-수요 매칭 추천 서비스 | D12: 초기 생성형 AI 기반 추천으로 시작, 운영 데이터 누적 후 데이터 기반 추천으로 진화. 지도·필터·찜·알림 포함 | E12: 20000000
B13: 1-5 | C13: 단기 임대 계약·일정 원스톱 서비스 | D13: 단기·팝업 특화 표준 양식, 캘린더 충돌 방지, 전자계약 API 연동 | E13: 10000000
B14: 1-6 | C14: 임대 신뢰 보증 솔루션 | D14: 등기등록부·도면·사진 등 서류 사전 검증·인증 마크 + 양방향 운영 후기·평점을 통합한 신뢰 기반. 첫 거래의 진입 장벽 완화 | E14: 25000000
B15: 1-7 | C15: 임대 분쟁 예방·조율 시스템 | D15: 입퇴실 표준 점검 절차·증빙 기록 + 분쟁 발생 시 사실 관계 기반 조율 워크플로우 | E15: 10000000
B16: 1-8 | C16: 공간 운영 분석 리포트 | D16: 체류·동선·재방문 데이터 분석, 임대인 정기 리포트 발송 | E16: 15000000
B18: 2 | C18: 아이템 · 청년 아이템·특산물의 시장 검증 | E18: =SUM(E19:E27) -> 140000000
B19: 2-1 | C19: 청년 아이템·지역 특산물 통합 큐레이션 허브 | D19: 생산자·상품·스토리 등록 DB, 카테고리·시즌·태그 메타 큐레이션 운영 | E19: 15000000
B20: 2-2 | C20: AI 매장 인테리어·진열 추천 서비스 | D20: 평수·업종·상품군 입력 시 무드보드·진열 동선 추천. 초기 프롬프트 기반으로 시작하고 운영 데이터 누적 후 데이터 기반 추천으로 진화 | E20: 15000000
B21: 2-3 | C21: 디지털 쇼룸 (3D/360 WebGL) 솔루션 | D21: 매장·상품 360도 체험, 오프라인 방문 전후 활용 | E21: 20000000
B22: 2-4 | C22: 커머스·자사몰 연동 시스템 | D22: 결제 PG·재고·자사몰 연동, 현장→자사몰 재구매 전환 | E22: 20000000
B23: 2-5 | C23: 테스트 팝업타운 운영 플랫폼 | D23: 청년·창작자의 시장 검증 통합 환경, 매출·반응·재방문 수집 | E23: 15000000
B24: 2-6 | C24: 팝업 오너 운영 대시보드 | D24: 입점 브랜드 전용 매출·재고·예약·운영 KPI 통합 대시보드 | E24: 10000000
B25: 2-7 | C25: AI 팝업 추천 코스 서비스 | D25: 방문객 타깃·테마·시즌별 추천 코스 제공 | E25: 15000000
B26: 2-8 | C26: 상품 자동 태깅·검색 서비스 | D26: LLM·비전 모델로 카테고리·키워드 자동 추출, 검색 정확도 향상 | E26: 10000000
B27: 2-9 | C27: 소상공인 정산·지원금 연계 도우미 | D27: 매출·정산 데이터 자동 집계 + 신청 가능 정부·지자체 지원금 매칭·신청 동선 안내. 세무 대행이 아닌 연계·안내 중심(홈택스·세무사 연결) | E27: 20000000
B29: 3 | C29: 이벤트 · 페스티벌·야시장·영화제의 디지털 운영 | E29: =SUM(E30:E35) -> 80000000
B30: 3-1 | C30: 이벤트 규모별(S/M/L/XL) 등록·운영 시스템 | D30: 행사 규모별 표준 양식·워크플로우. 운영팀 학습 부담 최소화 | E30: 15000000
B31: 3-2 | C31: 예약·예매 통합 플랫폼 | D31: 좌석·구역·시간대 예약, PG 연동, QR 티켓 발행 | E31: 15000000
B32: 3-3 | C32: 모바일 QR/NFC 체크인·스탬프 시스템 | D32: 별도 장비 불필요. 모바일만으로 입장·스탬프 랠리·동선 추적 | E32: 10000000
B33: 3-4 | C33: 실시간 행사 운영 대시보드 | D33: WebSocket 기반 실시간 입장자·매출·이슈 모니터링 | E33: 15000000
B34: 3-5 | C34: 이벤트 팀 협업·결산 자동화 워크플로우 | D34: 부스·인력·일정 분담, 행사 후 결산 리포트 발행 | E34: 10000000
B35: 3-6 | C35: 행사 안전·인파 관리 시스템 | D35: 실시간 인파 밀도·동선 모니터링, 안전 알림. 대형 행사 책임 대응 | E35: 15000000
B37: 4 | C37: 네트워크·시너지 · 거리 → 권역 → 광역 활성화 | E37: =SUM(E38:E43) -> 75000000
B38: 4-1 | C38: 미션·퀘스트 게이미피케이션 프로그램 | D38: 시민 참여형 동네 미션(도장 깨기), 유동·체류·재방문 증가 | E38: 10000000
B39: 4-2 | C39: 거리 → 권역 확산 진척 시각화 대시보드 | D39: 거리·권역별 성과 누적 시각화, 보고·홍보·차기 거리 선정 자료 | E39: 10000000
B40: 4-3 | C40: 차기 거점 거리 추천 서비스 | D40: 성과 데이터 기반 다음 확산 후보지 추천 | E40: 15000000
B41: 4-4 | C41: 사업 운영 통합 모니터링 대시보드 | D41: 10개 카테고리의 운영 데이터를 한 화면에 통합. 시계열·KPI·이슈 모니터링 | E41: 15000000
B42: 4-5 | C42: 권역 간 데이터 연동 플랫폼 | D42: RESTful API + Webhook, 인접 지역·다른 지자체 데이터 연동 | E42: 15000000
B43: 4-6 | C43: 자동 연계·시너지 알림 엔진 | D43: 성과·이벤트 발생 시 자동 푸시·알림톡, Retention 유도 | E43: 10000000
B45: 5 | C45: 멤버십·지역화폐 · 1회 방문자를 도시의 팬으로 | E45: =SUM(E46:E50) -> 60000000
B46: 5-1 | C46: 멤버십·등급 통합 인증 시스템 | D46: SSO 기반 통합 인증, 누적 활동 기반 등급·혜택 | E46: 10000000
B47: 5-2 | C47: 쿠폰·포인트 발행·정산 엔진 | D47: 지역 상점 사용 쿠폰·포인트 발행·QR 정산, 지자체 공동 발행 | E47: 15000000
B48: 5-3 | C48: 지역화폐 연동·정산 플랫폼 | D48: 기존 지자체 지역화폐 API 연동, 사업 결제 흐름이 곧 지역화폐 사용 확대 | E48: 15000000
...

Sheet 권역
B4: 권역 단계 — 권역(여러 거리) 활성화
B5: 단가 배수: ×1.7 (거리 기준) · 단위: 원 (₩) · 부가세 별도
B7: 코드 | C7: 솔루션명 | D7: 한 줄 설명 | E7: 단가 (원)
B8: 1 | C8: 공간 · 공실의 단기임대 활성화 / 청년의 무대, 지속가능한 팝업타운 | E8: =SUM(E9:E16) -> 229500000
B9: 1-1 | C9: 로컬 스토리 아카이브·콘텐츠 자산화 플랫폼 | D9: 동네 인물·노포·골목 서사를 위치·테마로 구조화 등록, QR 스토리·전시·오디오 가이드로 재가공. 사업 종료 후에도 남는 영구 콘텐츠 자산 | E9: 42500000
B10: 1-2 | C10: 임대 매물 등록·관리 시스템 | D10: 수요자·공급자 양방향 등록, 매물 정보·일정·상태 관리 | E10: 25500000
B11: 1-3 | C11: 공실 현황 GIS 지도 시스템 | D11: 지역 공실·매물을 지도에 실시간 표시, 권역·시기별 공실률·전환율 시각화. 지자체가 공실 분포를 한눈에 파악 | E11: 25500000
B12: 1-4 | C12: AI 매물-수요 매칭 추천 서비스 | D12: 초기 생성형 AI 기반 추천으로 시작, 운영 데이터 누적 후 데이터 기반 추천으로 진화. 지도·필터·찜·알림 포함 | E12: 34000000
B13: 1-5 | C13: 단기 임대 계약·일정 원스톱 서비스 | D13: 단기·팝업 특화 표준 양식, 캘린더 충돌 방지, 전자계약 API 연동 | E13: 17000000
B14: 1-6 | C14: 임대 신뢰 보증 솔루션 | D14: 등기등록부·도면·사진 등 서류 사전 검증·인증 마크 + 양방향 운영 후기·평점을 통합한 신뢰 기반. 첫 거래의 진입 장벽 완화 | E14: 42500000
B15: 1-7 | C15: 임대 분쟁 예방·조율 시스템 | D15: 입퇴실 표준 점검 절차·증빙 기록 + 분쟁 발생 시 사실 관계 기반 조율 워크플로우 | E15: 17000000
B16: 1-8 | C16: 공간 운영 분석 리포트 | D16: 체류·동선·재방문 데이터 분석, 임대인 정기 리포트 발송 | E16: 25500000
B18: 2 | C18: 아이템 · 청년 아이템·특산물의 시장 검증 | E18: =SUM(E19:E27) -> 238000000
B19: 2-1 | C19: 청년 아이템·지역 특산물 통합 큐레이션 허브 | D19: 생산자·상품·스토리 등록 DB, 카테고리·시즌·태그 메타 큐레이션 운영 | E19: 25500000
B20: 2-2 | C20: AI 매장 인테리어·진열 추천 서비스 | D20: 평수·업종·상품군 입력 시 무드보드·진열 동선 추천. 초기 프롬프트 기반으로 시작하고 운영 데이터 누적 후 데이터 기반 추천으로 진화 | E20: 25500000
B21: 2-3 | C21: 디지털 쇼룸 (3D/360 WebGL) 플랫폼 | D21: 매장·상품 360도 체험, 오프라인 방문 전후 활용 | E21: 34000000
B22: 2-4 | C22: 커머스·자사몰 연동 시스템 | D22: 결제 PG·재고·자사몰(Shopify·Cafe24) 연동, 현장→자사몰 재구매 전환 | E22: 34000000
B23: 2-5 | C23: 테스트 팝업타운 운영 플랫폼 | D23: 청년·창작자의 시장 검증 통합 환경, 매출·반응·재방문 수집 | E23: 25500000
B24: 2-6 | C24: 팝업 오너 운영 대시보드 | D24: 입점 브랜드 전용 매출·재고·예약·운영 KPI 통합 대시보드 | E24: 17000000
B25: 2-7 | C25: AI 팝업 추천 코스 서비스 | D25: 방문객 타깃·테마·시즌별 추천 코스 제공 | E25: 25500000
B26: 2-8 | C26: 상품 자동 태깅·검색 서비스 | D26: LLM·비전 모델로 카테고리·키워드 자동 추출, 검색 정확도 향상 | E26: 17000000
B27: 2-9 | C27: 소상공인 정산·지원금 연계 도우미 | D27: 매출·정산 데이터 자동 집계 + 신청 가능 정부·지자체 지원금 매칭·신청 동선 안내. 세무 대행이 아닌 연계·안내 중심(홈택스·세무사 연결) | E27: 34000000
B29: 3 | C29: 이벤트 · 페스티벌·야시장·영화제의 디지털 운영 | E29: =SUM(E30:E35) -> 136000000
B30: 3-1 | C30: 이벤트 규모별(S/M/L/XL) 등록·운영 시스템 | D30: 행사 규모별 표준 양식·워크플로우. 운영팀 학습 부담 최소화 | E30: 25500000
B31: 3-2 | C31: 예약·예매 통합 플랫폼 | D31: 좌석·구역·시간대 예약, PG 연동, QR 티켓 발행 | E31: 25500000
B32: 3-3 | C32: 모바일 QR/NFC 체크인·스탬프 시스템 | D32: 별도 장비 불필요. 모바일만으로 입장·스탬프 랠리·동선 추적 | E32: 17000000
B33: 3-4 | C33: 실시간 행사 운영 대시보드 | D33: WebSocket 기반 실시간 입장자·매출·이슈 모니터링 | E33: 25500000
B34: 3-5 | C34: 이벤트 팀 협업·결산 자동화 워크플로우 | D34: 부스·인력·일정 분담, 행사 후 결산 리포트 발행 | E34: 17000000
B35: 3-6 | C35: 행사 안전·인파 관리 시스템 | D35: 실시간 인파 밀도·동선 모니터링, 안전 알림. 대형 행사 책임 대응 | E35: 25500000
B37: 4 | C37: 네트워크·시너지 · 거리 → 권역 → 광역 활성화 | E37: =SUM(E38:E43) -> 127500000
B38: 4-1 | C38: 미션·퀘스트 게이미피케이션 프로그램 | D38: 시민 참여형 동네 미션(도장 깨기), 유동·체류·재방문 증가 | E38: 17000000
B39: 4-2 | C39: 거리 → 권역 확산 진척 시각화 대시보드 | D39: 거리·권역별 성과 누적 시각화, 보고·홍보·차기 거리 선정 자료 | E39: 17000000
B40: 4-3 | C40: 차기 거점 거리 추천 서비스 | D40: 성과 데이터 기반 다음 확산 후보지 추천 | E40: 25500000
B41: 4-4 | C41: 사업 운영 통합 모니터링 대시보드 | D41: 10개 카테고리의 운영 데이터를 한 화면에 통합. 시계열·KPI·이슈 모니터링 | E41: 25500000
B42: 4-5 | C42: 권역 간 데이터 연동 플랫폼 | D42: RESTful API + Webhook, 인접 지역·다른 지자체 데이터 연동 | E42: 25500000
B43: 4-6 | C43: 자동 연계·시너지 알림 엔진 | D43: 성과·이벤트 발생 시 자동 푸시·알림톡, Retention 유도 | E43: 17000000
B45: 5 | C45: 멤버십·지역화폐 · 1회 방문자를 도시의 팬으로 | E45: =SUM(E46:E50) -> 102000000
B46: 5-1 | C46: 멤버십·등급 통합 인증 시스템 | D46: SSO 기반 통합 인증, 누적 활동 기반 등급·혜택 | E46: 17000000
B47: 5-2 | C47: 쿠폰·포인트 발행·정산 엔진 | D47: 지역 상점 사용 쿠폰·포인트 발행·QR 정산, 지자체 공동 발행 | E47: 25500000
B48: 5-3 | C48: 지역화폐 연동·정산 플랫폼 | D48: 기존 지자체 지역화폐 API 연동, 사업 결제 흐름이 곧 지역화폐 사용 확대 | E48: 25500000
...

Sheet 광역
B4: 광역 단계 — 광역(시·도) 확산
B5: 단가 배수: ×3.0 (거리 기준) · 단위: 원 (₩) · 부가세 별도
B7: 코드 | C7: 솔루션명 | D7: 한 줄 설명 | E7: 단가 (원)
B8: 1 | C8: 공간 · 공실의 단기임대 활성화 / 청년의 무대, 지속가능한 팝업타운 | E8: =SUM(E9:E16) -> 405000000
B9: 1-1 | C9: 로컬 스토리 아카이브·콘텐츠 자산화 플랫폼 | D9: 동네 인물·노포·골목 서사를 위치·테마로 구조화 등록, QR 스토리·전시·오디오 가이드로 재가공. 사업 종료 후에도 남는 영구 콘텐츠 자산 | E9: 75000000
B10: 1-2 | C10: 임대 매물 등록·관리 시스템 | D10: 수요자·공급자 양방향 등록, 매물 정보·일정·상태 관리 | E10: 45000000
B11: 1-3 | C11: 공실 현황 GIS 지도 시스템 | D11: 지역 공실·매물을 지도에 실시간 표시, 권역·시기별 공실률·전환율 시각화. 지자체가 공실 분포를 한눈에 파악 | E11: 45000000
B12: 1-4 | C12: AI 매물-수요 매칭 추천 서비스 | D12: 초기 생성형 AI 기반 추천으로 시작, 운영 데이터 누적 후 데이터 기반 추천으로 진화. 지도·필터·찜·알림 포함 | E12: 60000000
B13: 1-5 | C13: 단기 임대 계약·일정 원스톱 서비스 | D13: 단기·팝업 특화 표준 양식, 캘린더 충돌 방지, 전자계약 API 연동 | E13: 30000000
B14: 1-6 | C14: 임대 신뢰 보증 솔루션 | D14: 등기등록부·도면·사진 등 서류 사전 검증·인증 마크 + 양방향 운영 후기·평점을 통합한 신뢰 기반. 첫 거래의 진입 장벽 완화 | E14: 75000000
B15: 1-7 | C15: 임대 분쟁 예방·조율 시스템 | D15: 입퇴실 표준 점검 절차·증빙 기록 + 분쟁 발생 시 사실 관계 기반 조율 워크플로우 | E15: 30000000
B16: 1-8 | C16: 공간 운영 분석 리포트 | D16: 체류·동선·재방문 데이터 분석, 임대인 정기 리포트 발송 | E16: 45000000
B18: 2 | C18: 아이템 · 청년 아이템·특산물의 시장 검증 | E18: =SUM(E19:E27) -> 420000000
B19: 2-1 | C19: 청년 아이템·지역 특산물 통합 큐레이션 허브 | D19: 생산자·상품·스토리 등록 DB, 카테고리·시즌·태그 메타 큐레이션 운영 | E19: 45000000
B20: 2-2 | C20: AI 매장 인테리어·진열 추천 서비스 | D20: 평수·업종·상품군 입력 시 무드보드·진열 동선 추천. 초기 프롬프트 기반으로 시작하고 운영 데이터 누적 후 데이터 기반 추천으로 진화 | E20: 45000000
B21: 2-3 | C21: 디지털 쇼룸 (3D/360 WebGL) 플랫폼 | D21: 매장·상품 360도 체험, 오프라인 방문 전후 활용 | E21: 60000000
B22: 2-4 | C22: 커머스·자사몰 연동 시스템 | D22: 결제 PG·재고·자사몰(Shopify·Cafe24) 연동, 현장→자사몰 재구매 전환 | E22: 60000000
B23: 2-5 | C23: 테스트 팝업타운 운영 플랫폼 | D23: 청년·창작자의 시장 검증 통합 환경, 매출·반응·재방문 수집 | E23: 45000000
B24: 2-6 | C24: 팝업 오너 운영 대시보드 | D24: 입점 브랜드 전용 매출·재고·예약·운영 KPI 통합 대시보드 | E24: 30000000
B25: 2-7 | C25: AI 팝업 추천 코스 서비스 | D25: 방문객 타깃·테마·시즌별 추천 코스 제공 | E25: 45000000
B26: 2-8 | C26: 상품 자동 태깅·검색 서비스 | D26: LLM·비전 모델로 카테고리·키워드 자동 추출, 검색 정확도 향상 | E26: 30000000
B27: 2-9 | C27: 소상공인 정산·지원금 연계 도우미 | D27: 매출·정산 데이터 자동 집계 + 신청 가능 정부·지자체 지원금 매칭·신청 동선 안내. 세무 대행이 아닌 연계·안내 중심(홈택스·세무사 연결) | E27: 60000000
B29: 3 | C29: 이벤트 · 페스티벌·야시장·영화제의 디지털 운영 | E29: =SUM(E30:E35) -> 240000000
B30: 3-1 | C30: 이벤트 규모별(S/M/L/XL) 등록·운영 시스템 | D30: 행사 규모별 표준 양식·워크플로우. 운영팀 학습 부담 최소화 | E30: 45000000
B31: 3-2 | C31: 예약·예매 통합 플랫폼 | D31: 좌석·구역·시간대 예약, PG 연동, QR 티켓 발행 | E31: 45000000
B32: 3-3 | C32: 모바일 QR/NFC 체크인·스탬프 시스템 | D32: 별도 장비 불필요. 모바일만으로 입장·스탬프 랠리·동선 추적 | E32: 30000000
B33: 3-4 | C33: 실시간 행사 운영 대시보드 | D33: WebSocket 기반 실시간 입장자·매출·이슈 모니터링 | E33: 45000000
B34: 3-5 | C34: 이벤트 팀 협업·결산 자동화 워크플로우 | D34: 부스·인력·일정 분담, 행사 후 결산 리포트 발행 | E34: 30000000
B35: 3-6 | C35: 행사 안전·인파 관리 시스템 | D35: 실시간 인파 밀도·동선 모니터링, 안전 알림. 대형 행사 책임 대응 | E35: 45000000
B37: 4 | C37: 네트워크·시너지 · 거리 → 권역 → 광역 활성화 | E37: =SUM(E38:E43) -> 225000000
B38: 4-1 | C38: 미션·퀘스트 게이미피케이션 프로그램 | D38: 시민 참여형 동네 미션(도장 깨기), 유동·체류·재방문 증가 | E38: 30000000
B39: 4-2 | C39: 거리 → 권역 확산 진척 시각화 대시보드 | D39: 거리·권역별 성과 누적 시각화, 보고·홍보·차기 거리 선정 자료 | E39: 30000000
B40: 4-3 | C40: 차기 거점 거리 추천 서비스 | D40: 성과 데이터 기반 다음 확산 후보지 추천 | E40: 45000000
B41: 4-4 | C41: 사업 운영 통합 모니터링 대시보드 | D41: 10개 카테고리의 운영 데이터를 한 화면에 통합. 시계열·KPI·이슈 모니터링 | E41: 45000000
B42: 4-5 | C42: 권역 간 데이터 연동 플랫폼 | D42: RESTful API + Webhook, 인접 지역·다른 지자체 데이터 연동 | E42: 45000000
B43: 4-6 | C43: 자동 연계·시너지 알림 엔진 | D43: 성과·이벤트 발생 시 자동 푸시·알림톡, Retention 유도 | E43: 30000000
B45: 5 | C45: 멤버십·지역화폐 · 1회 방문자를 도시의 팬으로 | E45: =SUM(E46:E50) -> 180000000
B46: 5-1 | C46: 멤버십·등급 통합 인증 시스템 | D46: SSO 기반 통합 인증, 누적 활동 기반 등급·혜택 | E46: 30000000
B47: 5-2 | C47: 쿠폰·포인트 발행·정산 엔진 | D47: 지역 상점 사용 쿠폰·포인트 발행·QR 정산, 지자체 공동 발행 | E47: 45000000
B48: 5-3 | C48: 지역화폐 연동·정산 플랫폼 | D48: 기존 지자체 지역화폐 API 연동, 사업 결제 흐름이 곧 지역화폐 사용 확대 | E48: 45000000
...

Sheet 요약
B4: 단계별 · 카테고리별 견적 합계
B5: 각 단계 시트에서 [도입] 체크 변경 시 자동 갱신 · 단위: 원 (₩) · 부가세 별도
B7: # | C7: 카테고리 | D7: 거리 | E7: 권역 | F7: 광역 | G7: 거리 비중
B8: 1 | C8: 공간 | D8: =거리!E8 -> 135000000 | E8: =권역!E8 -> 229500000 | F8: =광역!E8 -> 405000000 | G8: =IFERROR(D8/D19, 0) -> 0.14673913
B9: 2 | C9: 아이템 | D9: =거리!E18 -> 140000000 | E9: =권역!E18 -> 238000000 | F9: =광역!E18 -> 420000000 | G9: =IFERROR(D9/D19, 0) -> 0.15217391
B10: 3 | C10: 이벤트 | D10: =거리!E29 -> 80000000 | E10: =권역!E29 -> 136000000 | F10: =광역!E29 -> 240000000 | G10: =IFERROR(D10/D19, 0) -> 0.086956522
B11: 4 | C11: 네트워크·시너지 | D11: =거리!E37 -> 75000000 | E11: =권역!E37 -> 127500000 | F11: =광역!E37 -> 225000000 | G11: =IFERROR(D11/D19, 0) -> 0.081521739
B12: 5 | C12: 멤버십·지역화폐 | D12: =거리!E45 -> 60000000 | E12: =권역!E45 -> 102000000 | F12: =광역!E45 -> 180000000 | G12: =IFERROR(D12/D19, 0) -> 0.065217391
B13: 6 | C13: 성과 시각화·리포트 | D13: =거리!E52 -> 100000000 | E13: =권역!E52 -> 170000000 | F13: =광역!E52 -> 300000000 | G13: =IFERROR(D13/D19, 0) -> 0.10869565
B14: 7 | C14: 미션 베이스 인재 매칭 | D14: =거리!E61 -> 55000000 | E14: =권역!E61 -> 93500000 | F14: =광역!E61 -> 165000000 | G14: =IFERROR(D14/D19, 0) -> 0.059782609
B15: 8 | C15: 포용성·도시 가족 | D15: =거리!E68 -> 80000000 | E15: =권역!E68 -> 136000000 | F15: =광역!E68 -> 240000000 | G15: =IFERROR(D15/D19, 0) -> 0.086956522
B16: 9 | C16: 기업 유치·투자 | D16: =거리!E77 -> 65000000 | E16: =권역!E77 -> 110500000 | F16: =광역!E77 -> 195000000 | G16: =IFERROR(D16/D19, 0) -> 0.070652174
B17: 10 | C17: ESG | D17: =거리!E84 -> 60000000 | E17: =권역!E84 -> 102000000 | F17: =광역!E84 -> 180000000 | G17: =IFERROR(D17/D19, 0) -> 0.065217391
B18: 11 | C18: 기타 | D18: =거리!E91 -> 70000000 | E18: =권역!E91 -> 119000000 | F18: =광역!E91 -> 210000000 | G18: =IFERROR(D18/D19, 0) -> 0.076086957
B19: 총 합 계 | D19: =거리!E100 -> 920000000 | E19: =권역!E100 -> 1564000000 | F19: =광역!E100 -> 2760000000 | G19: 100.0%
B21: ※ 각 단계 시트의 [도입] 컬럼을 변경하면 본 표가 자동 갱신됩니다.
