Workbook

Sheet 개요
B4: [지역명] 팝업 타운 조성을 통한 상권 활성화 디지털 플랫폼 구축 사업
B5: 통합 견적서 v1.1 (Draft) · 솔루션 선택형
B6: 단위: 원 (₩) · 부가세 별도 · IT 영역
B10: 01 사업 개요
B11: 지역 골목 공실은 단순히 한 점포의 문제가 아니다. 한국부동산원에 따르면 2025년 3분기 전국 중대형 상가 공실률은 13.6%, 비수도권 1층 상가 공실률은 전국 평균을 크게 웃돈다. 그동안의 다양한 활성화 시도들이 단기 효과에 그쳤던 이유는 사람들이 다시 찾아오는 지속가능한 운영 구조를 만들지 못했기 때문이고, 그 본질은 공간마다 그 동네만의 고유성과 이야기가 충분히 담기지 않았기 때문이다.
B15: 본 사업은 각 동네의 이야기를 콘텐츠로 담아 사람들이 찾아오고 싶은 공간을 조성하고, 이를 진입 장벽이 낮은 단기 팝업 형태로 풀어내 임대인·청년 창작자·시민이 모두 부담 없이 참여할 수 있게 한다. 본 견적서는 10개 솔루션 카테고리로 구성되며, 각 솔루션은 독립적으로 도입·계약 가능하다. 단계별 시트(Street / Town / City)에서 도입할 솔루션만 체크하면 견적이 자동 합산된다.
B19: 02 사용 방법
B20: 1 | C20: 단계별 시트(Street / Town / City)를 펼친다. 각 단계마다 단가가 다르다.
B21: 2 | C21: 각 솔루션 행의 [도입] 컬럼에서 TRUE / FALSE를 선택한다 (드롭다운 제공).
B22: 3 | C22: 선택된 솔루션의 단가가 자동 합산되어 카테고리 소계·전체 합계가 갱신된다.
B23: 4 | C23: [요약] 시트에서 단계별·카테고리별 합계를 한눈에 비교할 수 있다.
B24: 5 | C24: 다른 도시에 적용할 때는 본 파일을 복사한 후 단가만 조정하면 그대로 템플릿 재활용 가능하다.
B27: 03 솔루션 카테고리 (10개)
B28: # | C28: 카테고리 | D28: 테마 | E28: 한 줄 소개
B29: 1 | C29: 공간 | D29: 공실의 단기임대 활성화 / 청년의 무대, 지속가능한 팝업타운 | E29: 지역 공실을 청년·창작자의 단기 팝업 무대로 전환하고, 동네 이야기와 결합해 지속가능한 팝업타운을 조성하는 핵심 인프라.
B30: 2 | C30: 아이템 | D30: 청년 아이템·특산물의 시장 검증 | E30: 청년 크리에이터·특산물 생산자가 좋은 상품을 도시 소비자에게 부담 없이 검증할 수 있는 IT 자산. AI 매장 운영 자동화로 작은 브랜드도 전문가급 매장 운영.
B31: 3 | C31: 이벤트 | D31: 페스티벌·야시장·영화제의 디지털 운영 | E31: 야시장·페스티벌·영화제 등 지역 행사를 거리 단위 작은 행사부터 광역 단위 대형 행사까지 동일 인프라로 운영. 운영 효율과 데이터 자산 동시 확보.
B32: 4 | C32: 네트워크·시너지 | D32: Street → Town → 도시 전체의 활성화 | E32: 거리 하나의 성공이 옆 거리, 타운, 도시 전체의 활력으로 누적·확산되는 단계적 모델을 시각화·자동화. 사업이 끝난 뒤에도 디지털 자산이 누적되어 다음 거리·다음 도시의 출발점이 된다.
B33: 5 | C33: 멤버십·지역화폐 | D33: 1회 방문자를 도시의 팬으로 | E33: 1회 방문을 지속 재방문·재구매로 전환하는 인센티브 구조. 기존 지자체 지역화폐와 연동해 본 사업의 모든 활동이 지자체 정책 효과 확장으로 이어진다.
B34: 6 | C34: 성과 시각화·리포트 | D34: 지자체 정책의 영구적 근거 자산 | E34: 운영 결과 데이터를 표준화된 형태로 시각화·리포트화. 지자체가 정책 효과를 즉시 보고, 향후 정책 결정·학술 연구·민간 협력에 활용.
B35: 7 | C35: 기타·프리미엄 운영 | D35: 시장 검증된 큰 운영 기능 | E35: 이미 시장에서 검증된 큰 운영 기능들. 단독으로도 임팩트가 큰 솔루션 모음.
B36: 8 | C36: 미션 베이스 인재 매칭 | D36: 차별화된 구인구직 | E36: 일반 시간·임금 위주 구인구직과 달리 비전·스토리·미션 기반. 본 사업의 캐릭터와 결이 같은 인재 매칭.
B37: 9 | C37: 포용성·도시 가족 | D37: 소도시 인구·정책 문제 대응 | E37: 소도시 인구·정책 문제 (고령화, 출산 장려, 다문화 등)에 대응하는 포용성 솔루션. 시민 만족도 직접 영향.
B38: 10 | C38: 기업 유치·투자 | D38: 빅브랜드·자본·기업 유치 | E38: 지역 활성화 데이터를 근거로 빅브랜드·자본·기업 유치. 지자체의 본질적 인구·세수·일자리 목표 직결.
B41: 04 색상 규약
C42: 노란 배경 + 굵은 글씨 | D42: 사용자 입력 셀 (도입 체크박스)
C43: 검은 배경 + 흰 글씨 | D43: 헤더 및 합계 행
C44: 베이지 배경 | D44: 카테고리 헤더
C45: 진한 베이지 | D45: 카테고리 소계
B48: 단가는 시장 일반 기준 산정이며, 사업 확정 단계에서 견적·계약 시 재산정한다.

Sheet Street
B4: 거리 단계 — 단일 거리 활성화
B5: 단가 배수: ×1.0 (Street 기준) · 단위: 원 (₩) · 부가세 별도
B7: 코드 | C7: 솔루션명 | D7: 한 줄 설명 | E7: 단가 (원) | F7: 도입 | G7: 소계 (원)
B8: 1 | C8: 공간 · 공실의 단기임대 활성화 / 청년의 무대, 지속가능한 팝업타운
B9: 1-1 | C9: 임대 자원 라이프사이클 통합 시스템 | D9: 수요자·공급자 양방향 등록·매물 관리·상태 추적 통합 워크플로우 | E9: 15000000 | F9: =TRUE() -> TRUE | G9: =IF(F9=TRUE(),E9,0) -> 15000000
B10: 1-2 | C10: AI 기반 매물-수요 적합도 매칭 엔진 | D10: 임베딩 기반 브랜드 성격×동네 톤 매칭 점수, 지도·필터·찜·알림 | E10: 20000000 | F10: =TRUE() -> TRUE | G10: =IF(F10=TRUE(),E10,0) -> 20000000
B11: 1-3 | C11: 단기 임대 계약·일정 오케스트레이션 플랫폼 | D11: 단기·팝업 특화 표준 양식, 캘린더 충돌 방지, 전자계약 API 연동 | E11: 10000000 | F11: =TRUE() -> TRUE | G11: =IF(F11=TRUE(),E11,0) -> 10000000
B12: 1-4 | C12: 시민 참여형 평판·신뢰 데이터 허브 | D12: 양방향 후기·누적 신뢰 점수·운영자 검증 마크 | E12: 10000000 | F12: =FALSE() -> FALSE | G12: =IF(F12=TRUE(),E12,0) -> 0
B13: 1-5 | C13: 운영자 매물 검증·승인 워크플로우 | D13: 사실 확인 큐, 이미지·키워드 부실 매물 자동 필터링, CS 통합 | E13: 15000000 | F13: =FALSE() -> FALSE | G13: =IF(F13=TRUE(),E13,0) -> 0
B14: 1-6 | C14: 입퇴실 사진 증빙·분쟁 예방 시스템 | D14: 차 렌트 입퇴실 사진 컨셉. 분쟁 발생 시 표준 증빙 자료 | E14: 10000000 | F14: =TRUE() -> TRUE | G14: =IF(F14=TRUE(),E14,0) -> 10000000
B15: 1-7 | C15: 공간 이용 분석 엔진 | D15: 체류 시간·동선·재방문 분석, 임대인 리포트 자동 발송 | E15: 15000000 | F15: =FALSE() -> FALSE | G15: =IF(F15=TRUE(),E15,0) -> 0
B16: 1. 공간 소계 | G16: =SUM(G9:G15) -> 55000000
B18: 2 | C18: 아이템 · 청년 아이템·특산물의 시장 검증
B19: 2-1 | C19: 청년 아이템·지역 특산물 통합 큐레이션 허브 | D19: 생산자·상품·스토리 등록 DB, 카테고리·시즌·태그 메타 큐레이션 운영 | E19: 15000000 | F19: =TRUE() -> TRUE | G19: =IF(F19=TRUE(),E19,0) -> 15000000
B20: 2-2 | C20: AI 팝업 인테리어·진열 자동 생성 엔진 | D20: 평수·업종·상품군 입력 → ML 모델이 무드보드·진열 동선 자동 생성 | E20: 15000000 | F20: =TRUE() -> TRUE | G20: =IF(F20=TRUE(),E20,0) -> 15000000
B21: 2-3 | C21: 디지털 쇼룸 (3D/360 WebGL) 플랫폼 | D21: 매장·상품 360도 체험, 오프라인 방문 전후 활용 | E21: 20000000 | F21: =FALSE() -> FALSE | G21: =IF(F21=TRUE(),E21,0) -> 0
B22: 2-4 | C22: 커머스·자사몰 연동 시스템 | D22: 결제 PG·재고·자사몰(Shopify·Cafe24) 연동, 현장→자사몰 재구매 전환 | E22: 20000000 | F22: =FALSE() -> FALSE | G22: =IF(F22=TRUE(),E22,0) -> 0
B23: 2-5 | C23: 테스트 팝업타운 운영 플랫폼 | D23: 청년·창작자의 시장 검증 통합 환경, 매출·반응·재방문 자동 수집 | E23: 15000000 | F23: =FALSE() -> FALSE | G23: =IF(F23=TRUE(),E23,0) -> 0
B24: 2-6 | C24: 팝업 오너(Owner) 운영 대시보드 | D24: 입점 브랜드 전용 매출·재고·예약·운영 KPI 통합 대시보드 | E24: 10000000 | F24: =TRUE() -> TRUE | G24: =IF(F24=TRUE(),E24,0) -> 10000000
B25: 2-7 | C25: AI 추천 코스·팝업 패키지 큐레이션 엔진 | D25: 방문객 타깃·테마·시즌별 추천 코스 자동 생성 | E25: 15000000 | F25: =FALSE() -> FALSE | G25: =IF(F25=TRUE(),E25,0) -> 0
B26: 2-8 | C26: 상품 자동 태깅·검색 엔진 | D26: LLM·비전 모델로 카테고리·키워드 자동 추출, 검색 정확도 향상 | E26: 10000000 | F26: =FALSE() -> FALSE | G26: =IF(F26=TRUE(),E26,0) -> 0
B27: 2. 아이템 소계 | G27: =SUM(G19:G26) -> 40000000
B29: 3 | C29: 이벤트 · 페스티벌·야시장·영화제의 디지털 운영
B30: 3-1 | C30: 이벤트 규모별(S/M/L/XL) 등록·운영 시스템 | D30: 행사 규모별 표준 양식·워크플로우. 운영팀 학습 부담 최소화 | E30: 15000000 | F30: =TRUE() -> TRUE | G30: =IF(F30=TRUE(),E30,0) -> 15000000
B31: 3-2 | C31: 예약·예매 통합 플랫폼 | D31: 좌석·구역·시간대 예약, PG 연동, QR 티켓 자동 발행 | E31: 15000000 | F31: =TRUE() -> TRUE | G31: =IF(F31=TRUE(),E31,0) -> 15000000
B32: 3-3 | C32: 모바일 QR/NFC 체크인·스탬프 시스템 | D32: 별도 장비 불필요. 모바일만으로 입장·스탬프 랠리·동선 추적 | E32: 10000000 | F32: =TRUE() -> TRUE | G32: =IF(F32=TRUE(),E32,0) -> 10000000
B33: 3-4 | C33: 실시간 행사 운영 대시보드 | D33: WebSocket 기반 실시간 입장자·매출·이슈 모니터링 | E33: 15000000 | F33: =FALSE() -> FALSE | G33: =IF(F33=TRUE(),E33,0) -> 0
B34: 3-5 | C34: 이벤트 팀 협업·결산 자동화 워크플로우 | D34: 부스·인력·일정 분담, 행사 후 결산 리포트 자동 생성 | E34: 10000000 | F34: =FALSE() -> FALSE | G34: =IF(F34=TRUE(),E34,0) -> 0
B35: 3-6 | C35: 행사 안전·인파 관리 시스템 | D35: 실시간 인파 밀도·동선 모니터링, 안전 알림. 대형 행사 책임 대응 | E35: 15000000 | F35: =FALSE() -> FALSE | G35: =IF(F35=TRUE(),E35,0) -> 0
B36: 3. 이벤트 소계 | G36: =SUM(G30:G35) -> 40000000
B38: 4 | C38: 네트워크·시너지 · Street → Town → 도시 전체의 활성화
B39: 4-1 | C39: 미션·퀘스트 게이미피케이션 프로그램 | D39: 시민 참여형 동네 미션(도장 깨기), 유동·체류·재방문 증가 | E39: 10000000 | F39: =TRUE() -> TRUE | G39: =IF(F39=TRUE(),E39,0) -> 10000000
B40: 4-2 | C40: Street → Town 확산 진척 시각화 대시보드 | D40: 거리·타운별 성과 누적 시각화, 보고·홍보·다음 거리 선정 자료 | E40: 10000000 | F40: =TRUE() -> TRUE | G40: =IF(F40=TRUE(),E40,0) -> 10000000
B41: 4-3 | C41: 다음 Street 추천 엔진 | D41: 성과 데이터 기반 다음 확산 후보지 자동 추천 | E41: 15000000 | F41: =FALSE() -> FALSE | G41: =IF(F41=TRUE(),E41,0) -> 0
B42: 4-4 | C42: 통합 운영 컨트롤 타워 | D42: 전 카테고리 데이터 단일 화면, 정책 의사결정 보조 | E42: 15000000 | F42: =TRUE() -> TRUE | G42: =IF(F42=TRUE(),E42,0) -> 15000000
B43: 4-5 | C43: 타운 간 데이터 연동 플랫폼 | D43: RESTful API + Webhook, 인접 지역·다른 지자체 데이터 연동 | E43: 15000000 | F43: =FALSE() -> FALSE | G43: =IF(F43=TRUE(),E43,0) -> 0
B44: 4-6 | C44: 자동 연계·시너지 알림 엔진 | D44: 성과·이벤트 발생 시 자동 푸시·알림톡, Retention 유도 | E44: 10000000 | F44: =TRUE() -> TRUE | G44: =IF(F44=TRUE(),E44,0) -> 10000000
B45: 4. 네트워크·시너지 소계 | G45: =SUM(G39:G44) -> 45000000
B47: 5 | C47: 멤버십·지역화폐 · 1회 방문자를 도시의 팬으로
B48: 5-1 | C48: 멤버십·등급 통합 인증 시스템 | D48: OAuth2·SSO 기반 통합 인증, 누적 활동 기반 등급·혜택 | E48: 10000000 | F48: =TRUE() -> TRUE | G48: =IF(F48=TRUE(),E48,0) -> 10000000
...

Sheet Town
B4: 타운 단계 — 타운 전체 활성화
B5: 단가 배수: ×1.7 (Street 기준) · 단위: 원 (₩) · 부가세 별도
B7: 코드 | C7: 솔루션명 | D7: 한 줄 설명 | E7: 단가 (원) | F7: 도입 | G7: 소계 (원)
B8: 1 | C8: 공간 · 공실의 단기임대 활성화 / 청년의 무대, 지속가능한 팝업타운
B9: 1-1 | C9: 임대 자원 라이프사이클 통합 시스템 | D9: 수요자·공급자 양방향 등록·매물 관리·상태 추적 통합 워크플로우 | E9: 25500000 | F9: =TRUE() -> TRUE | G9: =IF(F9=TRUE(),E9,0) -> 25500000
B10: 1-2 | C10: AI 기반 매물-수요 적합도 매칭 엔진 | D10: 임베딩 기반 브랜드 성격×동네 톤 매칭 점수, 지도·필터·찜·알림 | E10: 34000000 | F10: =TRUE() -> TRUE | G10: =IF(F10=TRUE(),E10,0) -> 34000000
B11: 1-3 | C11: 단기 임대 계약·일정 오케스트레이션 플랫폼 | D11: 단기·팝업 특화 표준 양식, 캘린더 충돌 방지, 전자계약 API 연동 | E11: 17000000 | F11: =TRUE() -> TRUE | G11: =IF(F11=TRUE(),E11,0) -> 17000000
B12: 1-4 | C12: 시민 참여형 평판·신뢰 데이터 허브 | D12: 양방향 후기·누적 신뢰 점수·운영자 검증 마크 | E12: 17000000 | F12: =FALSE() -> FALSE | G12: =IF(F12=TRUE(),E12,0) -> 0
B13: 1-5 | C13: 운영자 매물 검증·승인 워크플로우 | D13: 사실 확인 큐, 이미지·키워드 부실 매물 자동 필터링, CS 통합 | E13: 25500000 | F13: =FALSE() -> FALSE | G13: =IF(F13=TRUE(),E13,0) -> 0
B14: 1-6 | C14: 입퇴실 사진 증빙·분쟁 예방 시스템 | D14: 차 렌트 입퇴실 사진 컨셉. 분쟁 발생 시 표준 증빙 자료 | E14: 17000000 | F14: =TRUE() -> TRUE | G14: =IF(F14=TRUE(),E14,0) -> 17000000
B15: 1-7 | C15: 공간 이용 분석 엔진 | D15: 체류 시간·동선·재방문 분석, 임대인 리포트 자동 발송 | E15: 25500000 | F15: =FALSE() -> FALSE | G15: =IF(F15=TRUE(),E15,0) -> 0
B16: 1. 공간 소계 | G16: =SUM(G9:G15) -> 93500000
B18: 2 | C18: 아이템 · 청년 아이템·특산물의 시장 검증
B19: 2-1 | C19: 청년 아이템·지역 특산물 통합 큐레이션 허브 | D19: 생산자·상품·스토리 등록 DB, 카테고리·시즌·태그 메타 큐레이션 운영 | E19: 25500000 | F19: =TRUE() -> TRUE | G19: =IF(F19=TRUE(),E19,0) -> 25500000
B20: 2-2 | C20: AI 팝업 인테리어·진열 자동 생성 엔진 | D20: 평수·업종·상품군 입력 → ML 모델이 무드보드·진열 동선 자동 생성 | E20: 25500000 | F20: =TRUE() -> TRUE | G20: =IF(F20=TRUE(),E20,0) -> 25500000
B21: 2-3 | C21: 디지털 쇼룸 (3D/360 WebGL) 플랫폼 | D21: 매장·상품 360도 체험, 오프라인 방문 전후 활용 | E21: 34000000 | F21: =FALSE() -> FALSE | G21: =IF(F21=TRUE(),E21,0) -> 0
B22: 2-4 | C22: 커머스·자사몰 연동 시스템 | D22: 결제 PG·재고·자사몰(Shopify·Cafe24) 연동, 현장→자사몰 재구매 전환 | E22: 34000000 | F22: =FALSE() -> FALSE | G22: =IF(F22=TRUE(),E22,0) -> 0
B23: 2-5 | C23: 테스트 팝업타운 운영 플랫폼 | D23: 청년·창작자의 시장 검증 통합 환경, 매출·반응·재방문 자동 수집 | E23: 25500000 | F23: =FALSE() -> FALSE | G23: =IF(F23=TRUE(),E23,0) -> 0
B24: 2-6 | C24: 팝업 오너(Owner) 운영 대시보드 | D24: 입점 브랜드 전용 매출·재고·예약·운영 KPI 통합 대시보드 | E24: 17000000 | F24: =TRUE() -> TRUE | G24: =IF(F24=TRUE(),E24,0) -> 17000000
B25: 2-7 | C25: AI 추천 코스·팝업 패키지 큐레이션 엔진 | D25: 방문객 타깃·테마·시즌별 추천 코스 자동 생성 | E25: 25500000 | F25: =FALSE() -> FALSE | G25: =IF(F25=TRUE(),E25,0) -> 0
B26: 2-8 | C26: 상품 자동 태깅·검색 엔진 | D26: LLM·비전 모델로 카테고리·키워드 자동 추출, 검색 정확도 향상 | E26: 17000000 | F26: =FALSE() -> FALSE | G26: =IF(F26=TRUE(),E26,0) -> 0
B27: 2. 아이템 소계 | G27: =SUM(G19:G26) -> 68000000
B29: 3 | C29: 이벤트 · 페스티벌·야시장·영화제의 디지털 운영
B30: 3-1 | C30: 이벤트 규모별(S/M/L/XL) 등록·운영 시스템 | D30: 행사 규모별 표준 양식·워크플로우. 운영팀 학습 부담 최소화 | E30: 25500000 | F30: =TRUE() -> TRUE | G30: =IF(F30=TRUE(),E30,0) -> 25500000
B31: 3-2 | C31: 예약·예매 통합 플랫폼 | D31: 좌석·구역·시간대 예약, PG 연동, QR 티켓 자동 발행 | E31: 25500000 | F31: =TRUE() -> TRUE | G31: =IF(F31=TRUE(),E31,0) -> 25500000
B32: 3-3 | C32: 모바일 QR/NFC 체크인·스탬프 시스템 | D32: 별도 장비 불필요. 모바일만으로 입장·스탬프 랠리·동선 추적 | E32: 17000000 | F32: =TRUE() -> TRUE | G32: =IF(F32=TRUE(),E32,0) -> 17000000
B33: 3-4 | C33: 실시간 행사 운영 대시보드 | D33: WebSocket 기반 실시간 입장자·매출·이슈 모니터링 | E33: 25500000 | F33: =FALSE() -> FALSE | G33: =IF(F33=TRUE(),E33,0) -> 0
B34: 3-5 | C34: 이벤트 팀 협업·결산 자동화 워크플로우 | D34: 부스·인력·일정 분담, 행사 후 결산 리포트 자동 생성 | E34: 17000000 | F34: =FALSE() -> FALSE | G34: =IF(F34=TRUE(),E34,0) -> 0
B35: 3-6 | C35: 행사 안전·인파 관리 시스템 | D35: 실시간 인파 밀도·동선 모니터링, 안전 알림. 대형 행사 책임 대응 | E35: 25500000 | F35: =FALSE() -> FALSE | G35: =IF(F35=TRUE(),E35,0) -> 0
B36: 3. 이벤트 소계 | G36: =SUM(G30:G35) -> 68000000
B38: 4 | C38: 네트워크·시너지 · Street → Town → 도시 전체의 활성화
B39: 4-1 | C39: 미션·퀘스트 게이미피케이션 프로그램 | D39: 시민 참여형 동네 미션(도장 깨기), 유동·체류·재방문 증가 | E39: 17000000 | F39: =TRUE() -> TRUE | G39: =IF(F39=TRUE(),E39,0) -> 17000000
B40: 4-2 | C40: Street → Town 확산 진척 시각화 대시보드 | D40: 거리·타운별 성과 누적 시각화, 보고·홍보·다음 거리 선정 자료 | E40: 17000000 | F40: =TRUE() -> TRUE | G40: =IF(F40=TRUE(),E40,0) -> 17000000
B41: 4-3 | C41: 다음 Street 추천 엔진 | D41: 성과 데이터 기반 다음 확산 후보지 자동 추천 | E41: 25500000 | F41: =FALSE() -> FALSE | G41: =IF(F41=TRUE(),E41,0) -> 0
B42: 4-4 | C42: 통합 운영 컨트롤 타워 | D42: 전 카테고리 데이터 단일 화면, 정책 의사결정 보조 | E42: 25500000 | F42: =TRUE() -> TRUE | G42: =IF(F42=TRUE(),E42,0) -> 25500000
B43: 4-5 | C43: 타운 간 데이터 연동 플랫폼 | D43: RESTful API + Webhook, 인접 지역·다른 지자체 데이터 연동 | E43: 25500000 | F43: =FALSE() -> FALSE | G43: =IF(F43=TRUE(),E43,0) -> 0
B44: 4-6 | C44: 자동 연계·시너지 알림 엔진 | D44: 성과·이벤트 발생 시 자동 푸시·알림톡, Retention 유도 | E44: 17000000 | F44: =TRUE() -> TRUE | G44: =IF(F44=TRUE(),E44,0) -> 17000000
B45: 4. 네트워크·시너지 소계 | G45: =SUM(G39:G44) -> 76500000
B47: 5 | C47: 멤버십·지역화폐 · 1회 방문자를 도시의 팬으로
B48: 5-1 | C48: 멤버십·등급 통합 인증 시스템 | D48: OAuth2·SSO 기반 통합 인증, 누적 활동 기반 등급·혜택 | E48: 17000000 | F48: =TRUE() -> TRUE | G48: =IF(F48=TRUE(),E48,0) -> 17000000
...

Sheet City
B4: 광역 단계 — 다수 타운·광역 확산
B5: 단가 배수: ×3.0 (Street 기준) · 단위: 원 (₩) · 부가세 별도
B7: 코드 | C7: 솔루션명 | D7: 한 줄 설명 | E7: 단가 (원) | F7: 도입 | G7: 소계 (원)
B8: 1 | C8: 공간 · 공실의 단기임대 활성화 / 청년의 무대, 지속가능한 팝업타운
B9: 1-1 | C9: 임대 자원 라이프사이클 통합 시스템 | D9: 수요자·공급자 양방향 등록·매물 관리·상태 추적 통합 워크플로우 | E9: 45000000 | F9: =TRUE() -> TRUE | G9: =IF(F9=TRUE(),E9,0) -> 45000000
B10: 1-2 | C10: AI 기반 매물-수요 적합도 매칭 엔진 | D10: 임베딩 기반 브랜드 성격×동네 톤 매칭 점수, 지도·필터·찜·알림 | E10: 60000000 | F10: =TRUE() -> TRUE | G10: =IF(F10=TRUE(),E10,0) -> 60000000
B11: 1-3 | C11: 단기 임대 계약·일정 오케스트레이션 플랫폼 | D11: 단기·팝업 특화 표준 양식, 캘린더 충돌 방지, 전자계약 API 연동 | E11: 30000000 | F11: =TRUE() -> TRUE | G11: =IF(F11=TRUE(),E11,0) -> 30000000
B12: 1-4 | C12: 시민 참여형 평판·신뢰 데이터 허브 | D12: 양방향 후기·누적 신뢰 점수·운영자 검증 마크 | E12: 30000000 | F12: =FALSE() -> FALSE | G12: =IF(F12=TRUE(),E12,0) -> 0
B13: 1-5 | C13: 운영자 매물 검증·승인 워크플로우 | D13: 사실 확인 큐, 이미지·키워드 부실 매물 자동 필터링, CS 통합 | E13: 45000000 | F13: =FALSE() -> FALSE | G13: =IF(F13=TRUE(),E13,0) -> 0
B14: 1-6 | C14: 입퇴실 사진 증빙·분쟁 예방 시스템 | D14: 차 렌트 입퇴실 사진 컨셉. 분쟁 발생 시 표준 증빙 자료 | E14: 30000000 | F14: =TRUE() -> TRUE | G14: =IF(F14=TRUE(),E14,0) -> 30000000
B15: 1-7 | C15: 공간 이용 분석 엔진 | D15: 체류 시간·동선·재방문 분석, 임대인 리포트 자동 발송 | E15: 45000000 | F15: =FALSE() -> FALSE | G15: =IF(F15=TRUE(),E15,0) -> 0
B16: 1. 공간 소계 | G16: =SUM(G9:G15) -> 165000000
B18: 2 | C18: 아이템 · 청년 아이템·특산물의 시장 검증
B19: 2-1 | C19: 청년 아이템·지역 특산물 통합 큐레이션 허브 | D19: 생산자·상품·스토리 등록 DB, 카테고리·시즌·태그 메타 큐레이션 운영 | E19: 45000000 | F19: =TRUE() -> TRUE | G19: =IF(F19=TRUE(),E19,0) -> 45000000
B20: 2-2 | C20: AI 팝업 인테리어·진열 자동 생성 엔진 | D20: 평수·업종·상품군 입력 → ML 모델이 무드보드·진열 동선 자동 생성 | E20: 45000000 | F20: =TRUE() -> TRUE | G20: =IF(F20=TRUE(),E20,0) -> 45000000
B21: 2-3 | C21: 디지털 쇼룸 (3D/360 WebGL) 플랫폼 | D21: 매장·상품 360도 체험, 오프라인 방문 전후 활용 | E21: 60000000 | F21: =FALSE() -> FALSE | G21: =IF(F21=TRUE(),E21,0) -> 0
B22: 2-4 | C22: 커머스·자사몰 연동 시스템 | D22: 결제 PG·재고·자사몰(Shopify·Cafe24) 연동, 현장→자사몰 재구매 전환 | E22: 60000000 | F22: =FALSE() -> FALSE | G22: =IF(F22=TRUE(),E22,0) -> 0
B23: 2-5 | C23: 테스트 팝업타운 운영 플랫폼 | D23: 청년·창작자의 시장 검증 통합 환경, 매출·반응·재방문 자동 수집 | E23: 45000000 | F23: =FALSE() -> FALSE | G23: =IF(F23=TRUE(),E23,0) -> 0
B24: 2-6 | C24: 팝업 오너(Owner) 운영 대시보드 | D24: 입점 브랜드 전용 매출·재고·예약·운영 KPI 통합 대시보드 | E24: 30000000 | F24: =TRUE() -> TRUE | G24: =IF(F24=TRUE(),E24,0) -> 30000000
B25: 2-7 | C25: AI 추천 코스·팝업 패키지 큐레이션 엔진 | D25: 방문객 타깃·테마·시즌별 추천 코스 자동 생성 | E25: 45000000 | F25: =FALSE() -> FALSE | G25: =IF(F25=TRUE(),E25,0) -> 0
B26: 2-8 | C26: 상품 자동 태깅·검색 엔진 | D26: LLM·비전 모델로 카테고리·키워드 자동 추출, 검색 정확도 향상 | E26: 30000000 | F26: =FALSE() -> FALSE | G26: =IF(F26=TRUE(),E26,0) -> 0
B27: 2. 아이템 소계 | G27: =SUM(G19:G26) -> 120000000
B29: 3 | C29: 이벤트 · 페스티벌·야시장·영화제의 디지털 운영
B30: 3-1 | C30: 이벤트 규모별(S/M/L/XL) 등록·운영 시스템 | D30: 행사 규모별 표준 양식·워크플로우. 운영팀 학습 부담 최소화 | E30: 45000000 | F30: =TRUE() -> TRUE | G30: =IF(F30=TRUE(),E30,0) -> 45000000
B31: 3-2 | C31: 예약·예매 통합 플랫폼 | D31: 좌석·구역·시간대 예약, PG 연동, QR 티켓 자동 발행 | E31: 45000000 | F31: =TRUE() -> TRUE | G31: =IF(F31=TRUE(),E31,0) -> 45000000
B32: 3-3 | C32: 모바일 QR/NFC 체크인·스탬프 시스템 | D32: 별도 장비 불필요. 모바일만으로 입장·스탬프 랠리·동선 추적 | E32: 30000000 | F32: =TRUE() -> TRUE | G32: =IF(F32=TRUE(),E32,0) -> 30000000
B33: 3-4 | C33: 실시간 행사 운영 대시보드 | D33: WebSocket 기반 실시간 입장자·매출·이슈 모니터링 | E33: 45000000 | F33: =FALSE() -> FALSE | G33: =IF(F33=TRUE(),E33,0) -> 0
B34: 3-5 | C34: 이벤트 팀 협업·결산 자동화 워크플로우 | D34: 부스·인력·일정 분담, 행사 후 결산 리포트 자동 생성 | E34: 30000000 | F34: =FALSE() -> FALSE | G34: =IF(F34=TRUE(),E34,0) -> 0
B35: 3-6 | C35: 행사 안전·인파 관리 시스템 | D35: 실시간 인파 밀도·동선 모니터링, 안전 알림. 대형 행사 책임 대응 | E35: 45000000 | F35: =FALSE() -> FALSE | G35: =IF(F35=TRUE(),E35,0) -> 0
B36: 3. 이벤트 소계 | G36: =SUM(G30:G35) -> 120000000
B38: 4 | C38: 네트워크·시너지 · Street → Town → 도시 전체의 활성화
B39: 4-1 | C39: 미션·퀘스트 게이미피케이션 프로그램 | D39: 시민 참여형 동네 미션(도장 깨기), 유동·체류·재방문 증가 | E39: 30000000 | F39: =TRUE() -> TRUE | G39: =IF(F39=TRUE(),E39,0) -> 30000000
B40: 4-2 | C40: Street → Town 확산 진척 시각화 대시보드 | D40: 거리·타운별 성과 누적 시각화, 보고·홍보·다음 거리 선정 자료 | E40: 30000000 | F40: =TRUE() -> TRUE | G40: =IF(F40=TRUE(),E40,0) -> 30000000
B41: 4-3 | C41: 다음 Street 추천 엔진 | D41: 성과 데이터 기반 다음 확산 후보지 자동 추천 | E41: 45000000 | F41: =FALSE() -> FALSE | G41: =IF(F41=TRUE(),E41,0) -> 0
B42: 4-4 | C42: 통합 운영 컨트롤 타워 | D42: 전 카테고리 데이터 단일 화면, 정책 의사결정 보조 | E42: 45000000 | F42: =TRUE() -> TRUE | G42: =IF(F42=TRUE(),E42,0) -> 45000000
B43: 4-5 | C43: 타운 간 데이터 연동 플랫폼 | D43: RESTful API + Webhook, 인접 지역·다른 지자체 데이터 연동 | E43: 45000000 | F43: =FALSE() -> FALSE | G43: =IF(F43=TRUE(),E43,0) -> 0
B44: 4-6 | C44: 자동 연계·시너지 알림 엔진 | D44: 성과·이벤트 발생 시 자동 푸시·알림톡, Retention 유도 | E44: 30000000 | F44: =TRUE() -> TRUE | G44: =IF(F44=TRUE(),E44,0) -> 30000000
B45: 4. 네트워크·시너지 소계 | G45: =SUM(G39:G44) -> 135000000
B47: 5 | C47: 멤버십·지역화폐 · 1회 방문자를 도시의 팬으로
B48: 5-1 | C48: 멤버십·등급 통합 인증 시스템 | D48: OAuth2·SSO 기반 통합 인증, 누적 활동 기반 등급·혜택 | E48: 30000000 | F48: =TRUE() -> TRUE | G48: =IF(F48=TRUE(),E48,0) -> 30000000
...

Sheet 요약
B4: 단계별 · 카테고리별 견적 합계
B5: 각 단계 시트에서 [도입] 체크 변경 시 자동 갱신 · 단위: 원 (₩) · 부가세 별도
B7: # | C7: 카테고리 | D7: Street (거리) | E7: Town (타운) | F7: City (광역) | G7: Street 비중
B8: 1 | C8: 공간 | D8: =Street!G16 -> 55000000 | E8: =Town!G16 -> 93500000 | F8: =City!G16 -> 165000000 | G8: =IFERROR(D8/D18, 0) -> 0.19642857
B9: 2 | C9: 아이템 | D9: =Street!G27 -> 40000000 | E9: =Town!G27 -> 68000000 | F9: =City!G27 -> 120000000 | G9: =IFERROR(D9/D18, 0) -> 0.14285714
B10: 3 | C10: 이벤트 | D10: =Street!G36 -> 40000000 | E10: =Town!G36 -> 68000000 | F10: =City!G36 -> 120000000 | G10: =IFERROR(D10/D18, 0) -> 0.14285714
B11: 4 | C11: 네트워크·시너지 | D11: =Street!G45 -> 45000000 | E11: =Town!G45 -> 76500000 | F11: =City!G45 -> 135000000 | G11: =IFERROR(D11/D18, 0) -> 0.16071429
B12: 5 | C12: 멤버십·지역화폐 | D12: =Street!G53 -> 10000000 | E12: =Town!G53 -> 17000000 | F12: =City!G53 -> 30000000 | G12: =IFERROR(D12/D18, 0) -> 0.035714286
B13: 6 | C13: 성과 시각화·리포트 | D13: =Street!G62 -> 40000000 | E13: =Town!G62 -> 68000000 | F13: =City!G62 -> 120000000 | G13: =IFERROR(D13/D18, 0) -> 0.14285714
B14: 7 | C14: 기타·프리미엄 운영 | D14: =Street!G70 -> 10000000 | E14: =Town!G70 -> 17000000 | F14: =City!G70 -> 30000000 | G14: =IFERROR(D14/D18, 0) -> 0.035714286
B15: 8 | C15: 미션 베이스 인재 매칭 | D15: =Street!G78 -> 10000000 | E15: =Town!G78 -> 17000000 | F15: =City!G78 -> 30000000 | G15: =IFERROR(D15/D18, 0) -> 0.035714286
B16: 9 | C16: 포용성·도시 가족 | D16: =Street!G87 -> 20000000 | E16: =Town!G87 -> 34000000 | F16: =City!G87 -> 60000000 | G16: =IFERROR(D16/D18, 0) -> 0.071428571
B17: 10 | C17: 기업 유치·투자 | D17: =Street!G95 -> 10000000 | E17: =Town!G95 -> 17000000 | F17: =City!G95 -> 30000000 | G17: =IFERROR(D17/D18, 0) -> 0.035714286
B18: 총 합 계 | D18: =Street!G98 -> 280000000 | E18: =Town!G98 -> 476000000 | F18: =City!G98 -> 840000000 | G18: 100.0%
B20: ※ 각 단계 시트의 [도입] 컬럼을 변경하면 본 표가 자동 갱신됩니다.
